Workbook

Sheet Analysis 1
A2: Total HeadCount by average salary per Dept. | E2: %Left Employee Vs Total Employee per Dept. | J2: Row Labels | K2: Count of BONUS
A3: Department | B3: Average of SALARY2 | E3: column | F3: Column Labels | J3: Achiving
A4: Finance | B4: 87938.5 | E4: Department | F4: Active | G4: Left | H4: Grand Total | J4: Developing | K4: 1
A5: Human Resources | B5: 88223.692 | E5: Finance | F5: 0.1 | G5: 0.021428571 | H5: 0.12142857 | J5: Exceeding
A6: Information Technology | B6: 79893.409 | E6: Human Resources | F6: 0.10714286 | G6: 0.014285714 | H6: 0.12142857 | J6: Needs Improvement
A7: Marketing | B7: 86693.133 | E7: Information Technology | F7: 0.2 | G7: 0.042857143 | H7: 0.24285714 | J7: Outstanding
A8: Operations | B8: 77933.083 | E8: Marketing | F8: 0.11428571 | G8: 0.021428571 | H8: 0.13571429 | J8: Grand Total | K8: 1
A9: Sales | B9: 81083.353 | E9: Operations | F9: 0.12857143 | G9: 0.042857143 | H9: 0.17142857
A10: (blank) | E10: Sales | F10: 0.17857143 | G10: 0.028571429 | H10: 0.20714286
A11: Grand Total | B11: 82621.139 | E11: Grand Total | F11: 0.82857143 | G11: 0.17142857 | H11: 1
A16: Average Performance Btw Active Employee And Left Employee
B17: Column Labels
B18: Active | C18: Left | D18: Resigned | E18: (blank) | F18: Grand Total
A19: Average of Perf_Score | B19: 67.560345 | C19: 66.083333 | D19: 76.4 | E19: 65 | F19: 67.783439
A25: DASHBOARD CREATION

Sheet Raw_Employee_Data
A1: Emp ID | B1: First_Name | C1: Last_Name | D1: Merge Names | E1: Dept Code | F1: Hire Date | G1: Salary | H1: Perf_Score | I1: Employment Status | J1: DEPARTMENT | K1: SALARY2 | L1: YEAR OF SERVICE | M1: perf band | N1: BONUS
A2: EMP145 | B2: Thomas | C2: Jones | D2: =_xlfn.CONCAT(B2," ",C2) -> Thomas Jones | E2: MKT04 | F2: 11/11/2016 | G2: $50,936 | H2: 99 | I2: Active | J2: =VLOOKUP(E2,Lookup_Departments!$A$2:$A$7:'Lookup_Departments'!$B$2:$B$7,2,FALSE) -> Marketing | K2: =IF(G2=0,AVERAGEIF(J:J,J2,G:G),G2) -> $50,936 | L2: =ROUND(YEARFRAC(F2,TODAY()),2) -> 9.7 | M2: =_xlfn.IFS(H2<=49,"Needs Improvement",H2<=69,"Developing",H2<=84,"Achiving",H2<=94,"Exceeding",H2<=100,"Outstanding") -> Outstanding
A3: EMP053 | B3: Richard | C3: Williams | D3: =_xlfn.CONCAT(B3," ",C3) -> Richard Williams | E3: FIN03 | F3: 10/22/2015 | G3: 87938.5 | H3: 62 | I3: Active | J3: =VLOOKUP(E3,Lookup_Departments!$A$2:$A$7:'Lookup_Departments'!$B$2:$B$7,2,FALSE) -> Finance | K3: =IF(G3=0,AVERAGEIF(J:J,J3,G:G),G3) -> 87938.5 | L3: =ROUND(YEARFRAC(F3,TODAY()),2) -> 10.75 | M3: =_xlfn.IFS(H3<=49,"Needs Improvement",H3<=69,"Developing",H3<=84,"Achiving",H3<=94,"Exceeding",H3<=100,"Outstanding") -> Developing
A4: EMP028 | B4: Thomas | C4: Rodriguez | D4: =_xlfn.CONCAT(B4," ",C4) -> Thomas Rodriguez | E4: FIN03 | F4: 10/07/2019 | G4: 55920 | H4: 84 | I4: Active | J4: =VLOOKUP(E4,Lookup_Departments!$A$2:$A$7:'Lookup_Departments'!$B$2:$B$7,2,FALSE) -> Finance | K4: =IF(G4=0,AVERAGEIF(J:J,J4,G:G),G4) -> 55920 | L4: =ROUND(YEARFRAC(F4,TODAY()),2) -> 6.79 | M4: =_xlfn.IFS(H4<=49,"Needs Improvement",H4<=69,"Developing",H4<=84,"Achiving",H4<=94,"Exceeding",H4<=100,"Outstanding") -> Achiving
A5: EMP034 | B5: John | C5: Johnson | D5: =_xlfn.CONCAT(B5," ",C5) -> John Johnson | E5: IT02 | F5: 10/04/2023 | G5: 52287 | H5: 70 | I5: Active | J5: =VLOOKUP(E5,Lookup_Departments!$A$2:$A$7:'Lookup_Departments'!$B$2:$B$7,2,FALSE) -> Information Technology | K5: =IF(G5=0,AVERAGEIF(J:J,J5,G:G),G5) -> 52287 | L5: =ROUND(YEARFRAC(F5,TODAY()),2) -> 2.8 | M5: =_xlfn.IFS(H5<=49,"Needs Improvement",H5<=69,"Developing",H5<=84,"Achiving",H5<=94,"Exceeding",H5<=100,"Outstanding") -> Achiving
A6: EMP048 | B6: Richard | C6: Smith | D6: =_xlfn.CONCAT(B6," ",C6) -> Richard Smith | E6: HR01 | F6: 09/29/2018 | G6: $47,694 | H6: 75 | I6: Active | J6: =VLOOKUP(E6,Lookup_Departments!$A$2:$A$7:'Lookup_Departments'!$B$2:$B$7,2,FALSE) -> Human Resources | K6: =IF(G6=0,AVERAGEIF(J:J,J6,G:G),G6) -> $47,694 | L6: =ROUND(YEARFRAC(F6,TODAY()),2) -> 7.81 | M6: =_xlfn.IFS(H6<=49,"Needs Improvement",H6<=69,"Developing",H6<=84,"Achiving",H6<=94,"Exceeding",H6<=100,"Outstanding") -> Achiving
A7: EMP129 | B7: John | C7: Wilson | D7: =_xlfn.CONCAT(B7," ",C7) -> John Wilson | E7: SAL05 | F7: 09/24/2019 | G7: $77,610 | H7: 88 | I7: Active | J7: =VLOOKUP(E7,Lookup_Departments!$A$2:$A$7:'Lookup_Departments'!$B$2:$B$7,2,FALSE) -> Sales | K7: =IF(G7=0,AVERAGEIF(J:J,J7,G:G),G7) -> $77,610 | L7: =ROUND(YEARFRAC(F7,TODAY()),2) -> 6.83 | M7: =_xlfn.IFS(H7<=49,"Needs Improvement",H7<=69,"Developing",H7<=84,"Achiving",H7<=94,"Exceeding",H7<=100,"Outstanding") -> Exceeding
A8: EMP027 | B8: Sarah | C8: Miller | D8: =_xlfn.CONCAT(B8," ",C8) -> Sarah Miller | E8: OPS06 | F8: 09/09/2017 | G8: 57514 | H8: 65 | I8: Active | J8: =VLOOKUP(E8,Lookup_Departments!$A$2:$A$7:'Lookup_Departments'!$B$2:$B$7,2,FALSE) -> Operations | K8: =IF(G8=0,AVERAGEIF(J:J,J8,G:G),G8) -> 57514 | L8: =ROUND(YEARFRAC(F8,TODAY()),2) -> 8.87 | M8: =_xlfn.IFS(H8<=49,"Needs Improvement",H8<=69,"Developing",H8<=84,"Achiving",H8<=94,"Exceeding",H8<=100,"Outstanding") -> Developing
A9: EMP086 | B9: Emily | C9: Miller | D9: =_xlfn.CONCAT(B9," ",C9) -> Emily Miller | E9: SAL05 | F9: 09/07/2021 | G9: 70359 | H9: 74 | I9: Left | J9: =VLOOKUP(E9,Lookup_Departments!$A$2:$A$7:'Lookup_Departments'!$B$2:$B$7,2,FALSE) -> Sales | K9: =IF(G9=0,AVERAGEIF(J:J,J9,G:G),G9) -> 70359 | L9: =ROUND(YEARFRAC(F9,TODAY()),2) -> 4.88 | M9: =_xlfn.IFS(H9<=49,"Needs Improvement",H9<=69,"Developing",H9<=84,"Achiving",H9<=94,"Exceeding",H9<=100,"Outstanding") -> Achiving
A10: EMP130 | B10: Jane | C10: Garcia | D10: =_xlfn.CONCAT(B10," ",C10) -> Jane Garcia | E10: MKT04 | F10: 08/29/2021 | G10: 83007 | H10: 82 | I10: Active | J10: =VLOOKUP(E10,Lookup_Departments!$A$2:$A$7:'Lookup_Departments'!$B$2:$B$7,2,FALSE) -> Marketing | K10: =IF(G10=0,AVERAGEIF(J:J,J10,G:G),G10) -> 83007 | L10: =ROUND(YEARFRAC(F10,TODAY()),2) -> 4.9 | M10: =_xlfn.IFS(H10<=49,"Needs Improvement",H10<=69,"Developing",H10<=84,"Achiving",H10<=94,"Exceeding",H10<=100,"Outstanding") -> Achiving
A11: EMP077 | B11: Amanda | C11: Lopez | D11: =_xlfn.CONCAT(B11," ",C11) -> Amanda Lopez | E11: SAL05 | F11: 07/14/2016 | G11: 78402 | H11: 54 | I11: Active | J11: =VLOOKUP(E11,Lookup_Departments!$A$2:$A$7:'Lookup_Departments'!$B$2:$B$7,2,FALSE) -> Sales | K11: =IF(G11=0,AVERAGEIF(J:J,J11,G:G),G11) -> 78402 | L11: =ROUND(YEARFRAC(F11,TODAY()),2) -> 10.02 | M11: =_xlfn.IFS(H11<=49,"Needs Improvement",H11<=69,"Developing",H11<=84,"Achiving",H11<=94,"Exceeding",H11<=100,"Outstanding") -> Developing
A12: EMP004 | B12: Thomas | C12: Miller | D12: =_xlfn.CONCAT(B12," ",C12) -> Thomas Miller | E12: IT02 | F12: 07/10/2016 | G12: 74370 | H12: 82 | I12: Active | J12: =VLOOKUP(E12,Lookup_Departments!$A$2:$A$7:'Lookup_Departments'!$B$2:$B$7,2,FALSE) -> Information Technology | K12: =IF(G12=0,AVERAGEIF(J:J,J12,G:G),G12) -> 74370 | L12: =ROUND(YEARFRAC(F12,TODAY()),2) -> 10.03 | M12: =_xlfn.IFS(H12<=49,"Needs Improvement",H12<=69,"Developing",H12<=84,"Achiving",H12<=94,"Exceeding",H12<=100,"Outstanding") -> Achiving
A13: EMP068 | B13: Melissa | C13: Brown | D13: =_xlfn.CONCAT(B13," ",C13) -> Melissa Brown | E13: SAL05 | F13: 06/29/2022 | G13: 69219 | H13: 93 | I13: Active | J13: =VLOOKUP(E13,Lookup_Departments!$A$2:$A$7:'Lookup_Departments'!$B$2:$B$7,2,FALSE) -> Sales | K13: =IF(G13=0,AVERAGEIF(J:J,J13,G:G),G13) -> 69219 | L13: =ROUND(YEARFRAC(F13,TODAY()),2) -> 4.06 | M13: =_xlfn.IFS(H13<=49,"Needs Improvement",H13<=69,"Developing",H13<=84,"Achiving",H13<=94,"Exceeding",H13<=100,"Outstanding") -> Exceeding
A14: EMP092 | B14: Emily | C14: Johnson | D14: =_xlfn.CONCAT(B14," ",C14) -> Emily Johnson | E14: OPS06 | F14: 05/22/2016 | G14: 81167 | H14: 65 | I14: Active | J14: =VLOOKUP(E14,Lookup_Departments!$A$2:$A$7:'Lookup_Departments'!$B$2:$B$7,2,FALSE) -> Operations | K14: =IF(G14=0,AVERAGEIF(J:J,J14,G:G),G14) -> 81167 | L14: =ROUND(YEARFRAC(F14,TODAY()),2) -> 10.17 | M14: =_xlfn.IFS(H14<=49,"Needs Improvement",H14<=69,"Developing",H14<=84,"Achiving",H14<=94,"Exceeding",H14<=100,"Outstanding") -> Developing
A15: EMP089 | B15: Sarah | C15: Smith | D15: =_xlfn.CONCAT(B15," ",C15) -> Sarah Smith | E15: SAL05 | F15: 05/11/2023 | G15: $110,618 | H15: 88 | I15: Resigned | J15: =VLOOKUP(E15,Lookup_Departments!$A$2:$A$7:'Lookup_Departments'!$B$2:$B$7,2,FALSE) -> Sales | K15: =IF(G15=0,AVERAGEIF(J:J,J15,G:G),G15) -> $110,618 | L15: =ROUND(YEARFRAC(F15,TODAY()),2) -> 3.2 | M15: =_xlfn.IFS(H15<=49,"Needs Improvement",H15<=69,"Developing",H15<=84,"Achiving",H15<=94,"Exceeding",H15<=100,"Outstanding") -> Exceeding
A16: EMP039 | B16: Jane | C16: Miller | D16: =_xlfn.CONCAT(B16," ",C16) -> Jane Miller | E16: MKT04 | F16: 05/10/2017 | G16: 48748 | H16: 83 | I16: Active | J16: =VLOOKUP(E16,Lookup_Departments!$A$2:$A$7:'Lookup_Departments'!$B$2:$B$7,2,FALSE) -> Marketing | K16: =IF(G16=0,AVERAGEIF(J:J,J16,G:G),G16) -> 48748 | L16: =ROUND(YEARFRAC(F16,TODAY()),2) -> 9.2 | M16: =_xlfn.IFS(H16<=49,"Needs Improvement",H16<=69,"Developing",H16<=84,"Achiving",H16<=94,"Exceeding",H16<=100,"Outstanding") -> Achiving
A17: EMP138 | B17: Sarah | C17: Rodriguez | D17: =_xlfn.CONCAT(B17," ",C17) -> Sarah Rodriguez | E17: HR01 | F17: 04/20/2023 | G17: 115260 | H17: 77 | I17: Active | J17: =VLOOKUP(E17,Lookup_Departments!$A$2:$A$7:'Lookup_Departments'!$B$2:$B$7,2,FALSE) -> Human Resources | K17: =IF(G17=0,AVERAGEIF(J:J,J17,G:G),G17) -> 115260 | L17: =ROUND(YEARFRAC(F17,TODAY()),2) -> 3.26 | M17: =_xlfn.IFS(H17<=49,"Needs Improvement",H17<=69,"Developing",H17<=84,"Achiving",H17<=94,"Exceeding",H17<=100,"Outstanding") -> Achiving
A18: EMP035 | B18: John | C18: Jones | D18: =_xlfn.CONCAT(B18," ",C18) -> John Jones | E18: IT02 | F18: 03/08/2019 | G18: 79893.409 | H18: 33 | I18: Active | J18: =VLOOKUP(E18,Lookup_Departments!$A$2:$A$7:'Lookup_Departments'!$B$2:$B$7,2,FALSE) -> Information Technology | K18: =IF(G18=0,AVERAGEIF(J:J,J18,G:G),G18) -> 79893.409 | L18: =ROUND(YEARFRAC(F18,TODAY()),2) -> 7.37 | M18: =_xlfn.IFS(H18<=49,"Needs Improvement",H18<=69,"Developing",H18<=84,"Achiving",H18<=94,"Exceeding",H18<=100,"Outstanding") -> Needs Improvement
A19: EMP040 | B19: Jane | C19: Rodriguez | D19: =_xlfn.CONCAT(B19," ",C19) -> Jane Rodriguez | E19: IT02 | F19: 02/19/2017 | G19: $86,246 | H19: 61 | I19: Active | J19: =VLOOKUP(E19,Lookup_Departments!$A$2:$A$7:'Lookup_Departments'!$B$2:$B$7,2,FALSE) -> Information Technology | K19: =IF(G19=0,AVERAGEIF(J:J,J19,G:G),G19) -> $86,246 | L19: =ROUND(YEARFRAC(F19,TODAY()),2) -> 9.43 | M19: =_xlfn.IFS(H19<=49,"Needs Improvement",H19<=69,"Developing",H19<=84,"Achiving",H19<=94,"Exceeding",H19<=100,"Outstanding") -> Developing
A20: EMP033 | B20: David | C20: Martinez | D20: =_xlfn.CONCAT(B20," ",C20) -> David Martinez | E20: HR01 | F20: 02/07/2018 | G20: 91655 | H20: 95 | I20: Active | J20: =VLOOKUP(E20,Lookup_Departments!$A$2:$A$7:'Lookup_Departments'!$B$2:$B$7,2,FALSE) -> Human Resources | K20: =IF(G20=0,AVERAGEIF(J:J,J20,G:G),G20) -> 91655 | L20: =ROUND(YEARFRAC(F20,TODAY()),2) -> 8.46 | M20: =_xlfn.IFS(H20<=49,"Needs Improvement",H20<=69,"Developing",H20<=84,"Achiving",H20<=94,"Exceeding",H20<=100,"Outstanding") -> Outstanding
A21: EMP122 | C21: Jones | D21: =_xlfn.CONCAT(B21," ",C21) -> Jones | E21: IT02 | F21: 01/12/2019 | G21: 112887 | H21: 59 | I21: Active | J21: =VLOOKUP(E21,Lookup_Departments!$A$2:$A$7:'Lookup_Departments'!$B$2:$B$7,2,FALSE) -> Information Technology | K21: =IF(G21=0,AVERAGEIF(J:J,J21,G:G),G21) -> 112887 | L21: =ROUND(YEARFRAC(F21,TODAY()),2) -> 7.53 | M21: =_xlfn.IFS(H21<=49,"Needs Improvement",H21<=69,"Developing",H21<=84,"Achiving",H21<=94,"Exceeding",H21<=100,"Outstanding") -> Developing
A22: EMP096 | B22: John | C22: Wilson | D22: =_xlfn.CONCAT(B22," ",C22) -> John Wilson | E22: OPS06 | F22: 45272 | G22: 59980 | H22: 70 | I22: Left | J22: =VLOOKUP(E22,Lookup_Departments!$A$2:$A$7:'Lookup_Departments'!$B$2:$B$7,2,FALSE) -> Operations | K22: =IF(G22=0,AVERAGEIF(J:J,J22,G:G),G22) -> 59980 | L22: =ROUND(YEARFRAC(F22,TODAY()),2) -> 2.61 | M22: =_xlfn.IFS(H22<=49,"Needs Improvement",H22<=69,"Developing",H22<=84,"Achiving",H22<=94,"Exceeding",H22<=100,"Outstanding") -> Achiving
A23: EMP061 | B23: Emily | C23: Brown | D23: =_xlfn.CONCAT(B23," ",C23) -> Emily Brown | E23: IT02 | F23: 45255 | G23: 49435 | H23: 65 | I23: Left | J23: =VLOOKUP(E23,Lookup_Departments!$A$2:$A$7:'Lookup_Departments'!$B$2:$B$7,2,FALSE) -> Information Technology | K23: =IF(G23=0,AVERAGEIF(J:J,J23,G:G),G23) -> 49435 | L23: =ROUND(YEARFRAC(F23,TODAY()),2) -> 2.66 | M23: =_xlfn.IFS(H23<=49,"Needs Improvement",H23<=69,"Developing",H23<=84,"Achiving",H23<=94,"Exceeding",H23<=100,"Outstanding") -> Developing
A24: EMP102 | B24: Emily | C24: Wilson | D24: =_xlfn.CONCAT(B24," ",C24) -> Emily Wilson | E24: SAL05 | F24: 45217 | G24: 110381 | H24: 93 | I24: Active | J24: =VLOOKUP(E24,Lookup_Departments!$A$2:$A$7:'Lookup_Departments'!$B$2:$B$7,2,FALSE) -> Sales | K24: =IF(G24=0,AVERAGEIF(J:J,J24,G:G),G24) -> 110381 | L24: =ROUND(YEARFRAC(F24,TODAY()),2) -> 2.76 | M24: =_xlfn.IFS(H24<=49,"Needs Improvement",H24<=69,"Developing",H24<=84,"Achiving",H24<=94,"Exceeding",H24<=100,"Outstanding") -> Exceeding
A25: EMP137 | B25: Michael | C25: Johnson | D25: =_xlfn.CONCAT(B25," ",C25) -> Michael Johnson | E25: IT02 | F25: 45195 | G25: 66069 | H25: 72 | I25: Active | J25: =VLOOKUP(E25,Lookup_Departments!$A$2:$A$7:'Lookup_Departments'!$B$2:$B$7,2,FALSE) -> Information Technology | K25: =IF(G25=0,AVERAGEIF(J:J,J25,G:G),G25) -> 66069 | L25: =ROUND(YEARFRAC(F25,TODAY()),2) -> 2.82 | M25: =_xlfn.IFS(H25<=49,"Needs Improvement",H25<=69,"Developing",H25<=84,"Achiving",H25<=94,"Exceeding",H25<=100,"Outstanding") -> Achiving
A26: EMP114 | B26: Melissa | C26: Wilson | D26: =_xlfn.CONCAT(B26," ",C26) -> Melissa Wilson | E26: IT02 | F26: 45171 | G26: 83724 | H26: 81 | I26: Resigned | J26: =VLOOKUP(E26,Lookup_Departments!$A$2:$A$7:'Lookup_Departments'!$B$2:$B$7,2,FALSE) -> Information Technology | K26: =IF(G26=0,AVERAGEIF(J:J,J26,G:G),G26) -> 83724 | L26: =ROUND(YEARFRAC(F26,TODAY()),2) -> 2.89 | M26: =_xlfn.IFS(H26<=49,"Needs Improvement",H26<=69,"Developing",H26<=84,"Achiving",H26<=94,"Exceeding",H26<=100,"Outstanding") -> Achiving
A27: EMP031 | B27: Thomas | C27: Rodriguez | D27: =_xlfn.CONCAT(B27," ",C27) -> Thomas Rodriguez | E27: SAL05 | F27: 45169 | G27: 65290 | H27: 77 | I27: Active | J27: =VLOOKUP(E27,Lookup_Departments!$A$2:$A$7:'Lookup_Departments'!$B$2:$B$7,2,FALSE) -> Sales | K27: =IF(G27=0,AVERAGEIF(J:J,J27,G:G),G27) -> 65290 | L27: =ROUND(YEARFRAC(F27,TODAY()),2) -> 2.89 | M27: =_xlfn.IFS(H27<=49,"Needs Improvement",H27<=69,"Developing",H27<=84,"Achiving",H27<=94,"Exceeding",H27<=100,"Outstanding") -> Achiving
A28: EMP052 | C28: Williams | D28: =_xlfn.CONCAT(B28," ",C28) -> Williams | E28: SAL05 | F28: 45134 | G28: 81205 | H28: 59 | I28: Active | J28: =VLOOKUP(E28,Lookup_Departments!$A$2:$A$7:'Lookup_Departments'!$B$2:$B$7,2,FALSE) -> Sales | K28: =IF(G28=0,AVERAGEIF(J:J,J28,G:G),G28) -> 81205 | L28: =ROUND(YEARFRAC(F28,TODAY()),2) -> 2.99 | M28: =_xlfn.IFS(H28<=49,"Needs Improvement",H28<=69,"Developing",H28<=84,"Achiving",H28<=94,"Exceeding",H28<=100,"Outstanding") -> Developing
A29: EMP042 | B29: Jane | C29: Anderson | D29: =_xlfn.CONCAT(B29," ",C29) -> Jane Anderson | E29: IT02 | F29: 45112 | G29: 79893.409 | H29: 54 | I29: Active | J29: =VLOOKUP(E29,Lookup_Departments!$A$2:$A$7:'Lookup_Departments'!$B$2:$B$7,2,FALSE) -> Information Technology | K29: =IF(G29=0,AVERAGEIF(J:J,J29,G:G),G29) -> 79893.409 | L29: =ROUND(YEARFRAC(F29,TODAY()),2) -> 3.05 | M29: =_xlfn.IFS(H29<=49,"Needs Improvement",H29<=69,"Developing",H29<=84,"Achiving",H29<=94,"Exceeding",H29<=100,"Outstanding") -> Developing
A30: EMP139 | B30: John | C30: Martinez | D30: =_xlfn.CONCAT(B30," ",C30) -> John Martinez | E30: FIN03 | F30: 45110 | G30: 103831 | H30: 70 | I30: Active | J30: =VLOOKUP(E30,Lookup_Departments!$A$2:$A$7:'Lookup_Departments'!$B$2:$B$7,2,FALSE) -> Finance | K30: =IF(G30=0,AVERAGEIF(J:J,J30,G:G),G30) -> 103831 | L30: =ROUND(YEARFRAC(F30,TODAY()),2) -> 3.05 | M30: =_xlfn.IFS(H30<=49,"Needs Improvement",H30<=69,"Developing",H30<=84,"Achiving",H30<=94,"Exceeding",H30<=100,"Outstanding") -> Achiving
A31: EMP044 | B31: William | C31: Davis | D31: =_xlfn.CONCAT(B31," ",C31) -> William Davis | E31: IT02 | F31: 45055 | G31: $49,942 | H31: 51 | I31: Active | J31: =VLOOKUP(E31,Lookup_Departments!$A$2:$A$7:'Lookup_Departments'!$B$2:$B$7,2,FALSE) -> Information Technology | K31: =IF(G31=0,AVERAGEIF(J:J,J31,G:G),G31) -> $49,942 | L31: =ROUND(YEARFRAC(F31,TODAY()),2) -> 3.2 | M31: =_xlfn.IFS(H31<=49,"Needs Improvement",H31<=69,"Developing",H31<=84,"Achiving",H31<=94,"Exceeding",H31<=100,"Outstanding") -> Developing
A32: EMP021 | B32: William | C32: Rodriguez | D32: =_xlfn.CONCAT(B32," ",C32) -> William Rodriguez | E32: FIN03 | F32: 45037 | G32: 85457 | H32: 79 | I32: Active | J32: =VLOOKUP(E32,Lookup_Departments!$A$2:$A$7:'Lookup_Departments'!$B$2:$B$7,2,FALSE) -> Finance | K32: =IF(G32=0,AVERAGEIF(J:J,J32,G:G),G32) -> 85457 | L32: =ROUND(YEARFRAC(F32,TODAY()),2) -> 3.25 | M32: =_xlfn.IFS(H32<=49,"Needs Improvement",H32<=69,"Developing",H32<=84,"Achiving",H32<=94,"Exceeding",H32<=100,"Outstanding") -> Achiving
A33: EMP075 | B33: Richard | C33: Davis | D33: =_xlfn.CONCAT(B33," ",C33) -> Richard Davis | E33: HR01 | F33: 44991 | G33: 106896 | H33: 52 | I33: Left | J33: =VLOOKUP(E33,Lookup_Departments!$A$2:$A$7:'Lookup_Departments'!$B$2:$B$7,2,FALSE) -> Human Resources | K33: =IF(G33=0,AVERAGEIF(J:J,J33,G:G),G33) -> 106896 | L33: =ROUND(YEARFRAC(F33,TODAY()),2) -> 3.38 | M33: =_xlfn.IFS(H33<=49,"Needs Improvement",H33<=69,"Developing",H33<=84,"Achiving",H33<=94,"Exceeding",H33<=100,"Outstanding") -> Developing
A34: EMP112 | B34: Thomas | C34: Smith | D34: =_xlfn.CONCAT(B34," ",C34) -> Thomas Smith | E34: IT02 | F34: 44977 | G34: 73785 | H34: 40 | I34: Left | J34: =VLOOKUP(E34,Lookup_Departments!$A$2:$A$7:'Lookup_Departments'!$B$2:$B$7,2,FALSE) -> Information Technology | K34: =IF(G34=0,AVERAGEIF(J:J,J34,G:G),G34) -> 73785 | L34: =ROUND(YEARFRAC(F34,TODAY()),2) -> 3.42 | M34: =_xlfn.IFS(H34<=49,"Needs Improvement",H34<=69,"Developing",H34<=84,"Achiving",H34<=94,"Exceeding",H34<=100,"Outstanding") -> Needs Improvement
A35: EMP003 | B35: Melissa | C35: Rodriguez | D35: =_xlfn.CONCAT(B35," ",C35) -> Melissa Rodriguez | E35: OPS06 | F35: 44930 | G35: 60623 | H35: 78 | I35: Active | J35: =VLOOKUP(E35,Lookup_Departments!$A$2:$A$7:'Lookup_Departments'!$B$2:$B$7,2,FALSE) -> Operations | K35: =IF(G35=0,AVERAGEIF(J:J,J35,G:G),G35) -> 60623 | L35: =ROUND(YEARFRAC(F35,TODAY()),2) -> 3.55 | M35: =_xlfn.IFS(H35<=49,"Needs Improvement",H35<=69,"Developing",H35<=84,"Achiving",H35<=94,"Exceeding",H35<=100,"Outstanding") -> Achiving
A36: EMP103 | B36: Amanda | C36: Brown | D36: =_xlfn.CONCAT(B36," ",C36) -> Amanda Brown | E36: IT02 | F36: 44848 | G36: $118,634 | H36: 91 | I36: Active | J36: =VLOOKUP(E36,Lookup_Departments!$A$2:$A$7:'Lookup_Departments'!$B$2:$B$7,2,FALSE) -> Information Technology | K36: =IF(G36=0,AVERAGEIF(J:J,J36,G:G),G36) -> $118,634 | L36: =ROUND(YEARFRAC(F36,TODAY()),2) -> 3.77 | M36: =_xlfn.IFS(H36<=49,"Needs Improvement",H36<=69,"Developing",H36<=84,"Achiving",H36<=94,"Exceeding",H36<=100,"Outstanding") -> Exceeding
A37: EMP091 | B37: Thomas | C37: Davis | D37: =_xlfn.CONCAT(B37," ",C37) -> Thomas Davis | E37: OPS06 | F37: 44827 | G37: 77933.083 | H37: 46 | I37: Left | J37: =VLOOKUP(E37,Lookup_Departments!$A$2:$A$7:'Lookup_Departments'!$B$2:$B$7,2,FALSE) -> Operations | K37: =IF(G37=0,AVERAGEIF(J:J,J37,G:G),G37) -> 77933.083 | L37: =ROUND(YEARFRAC(F37,TODAY()),2) -> 3.83 | M37: =_xlfn.IFS(H37<=49,"Needs Improvement",H37<=69,"Developing",H37<=84,"Achiving",H37<=94,"Exceeding",H37<=100,"Outstanding") -> Needs Improvement
A38: EMP041 | B38: James | C38: Gonzalez | D38: =_xlfn.CONCAT(B38," ",C38) -> James Gonzalez | E38: SAL05 | F38: 44819 | G38: 81083.353 | H38: 65 | I38: Left | J38: =VLOOKUP(E38,Lookup_Departments!$A$2:$A$7:'Lookup_Departments'!$B$2:$B$7,2,FALSE) -> Sales | K38: =IF(G38=0,AVERAGEIF(J:J,J38,G:G),G38) -> 81083.353 | L38: =ROUND(YEARFRAC(F38,TODAY()),2) -> 3.85 | M38: =_xlfn.IFS(H38<=49,"Needs Improvement",H38<=69,"Developing",H38<=84,"Achiving",H38<=94,"Exceeding",H38<=100,"Outstanding") -> Developing
A39: EMP010 | B39: Michael | C39: Rodriguez | D39: =_xlfn.CONCAT(B39," ",C39) -> Michael Rodriguez | E39: IT02 | F39: 44815 | G39: 93956 | H39: 50 | I39: Left | J39: =VLOOKUP(E39,Lookup_Departments!$A$2:$A$7:'Lookup_Departments'!$B$2:$B$7,2,FALSE) -> Information Technology | K39: =IF(G39=0,AVERAGEIF(J:J,J39,G:G),G39) -> 93956 | L39: =ROUND(YEARFRAC(F39,TODAY()),2) -> 3.86 | M39: =_xlfn.IFS(H39<=49,"Needs Improvement",H39<=69,"Developing",H39<=84,"Achiving",H39<=94,"Exceeding",H39<=100,"Outstanding") -> Developing
A40: EMP043 | B40: John | C40: Wilson | D40: =_xlfn.CONCAT(B40," ",C40) -> John Wilson | E40: OPS06 | F40: 44776 | G40: 111845 | H40: 98 | I40: Active | J40: =VLOOKUP(E40,Lookup_Departments!$A$2:$A$7:'Lookup_Departments'!$B$2:$B$7,2,FALSE) -> Operations | K40: =IF(G40=0,AVERAGEIF(J:J,J40,G:G),G40) -> 111845 | L40: =ROUND(YEARFRAC(F40,TODAY()),2) -> 3.97 | M40: =_xlfn.IFS(H40<=49,"Needs Improvement",H40<=69,"Developing",H40<=84,"Achiving",H40<=94,"Exceeding",H40<=100,"Outstanding") -> Outstanding
...

Sheet Lookup_Departments
A1: Dept_Code | B1: Department_Name
A2: HR01 | B2: Human Resources
A3: IT02 | B3: Information Technology
A4: FIN03 | B4: Finance
A5: MKT04 | B5: Marketing
A6: SAL05 | B6: Sales
A7: OPS06 | B7: Operations

Sheet Lookup_Performance
A1: Min_Score | B1: Max_Score | C1: Performance_Band | D1: Bonus_Percentage
A2: 0 | B2: 49 | C2: Needs Improvement | D2: 0
A3: 50 | B3: 69 | C3: Developing | D3: 0.02
A4: 70 | B4: 84 | C4: Achieving | D4: 0.05
A5: 85 | B5: 94 | C5: Exceeding | D5: 0.08
A6: 95 | B6: 100 | C6: Outstanding | D6: 0.12

Sheet Detail1
A1: Details for column - Employment Status: Active
A3: Emp ID | B3: First_Name | C3: Last_Name | D3: Column2 | E3: Dept Code | F3: Hire Date | G3: Salary | H3: Perf_Score | I3: Employment Status | J3: DEPARTMENT | K3: SALARY2 | L3: YEAR OF SERVICE | M3: perf band | N3: BONUS
A4: EMP139 | B4: John | C4: Martinez | D4: John Martinez | E4: FIN03 | F4: 45110 | G4: 103831 | H4: 70 | I4: Active | J4: Finance | K4: 103831 | L4: 3.03 | M4: Achiving
A5: EMP095 | C5: Rodriguez | D5: Rodriguez | E5: FIN03 | F5: 43107 | G5: 102139 | H5: 79 | I5: Active | J5: Finance | K5: 102139 | L5: 8.52 | M5: Achiving
A6: EMP019 | B6: Michael | C6: Hernandez | D6: Michael Hernandez | E6: FIN03 | F6: 43076 | G6: 118527 | H6: 50 | I6: Active | J6: Finance | K6: 118527 | L6: 8.61 | M6: Developing
A7: EMP021 | B7: William | C7: Rodriguez | D7: William Rodriguez | E7: FIN03 | F7: 45037 | G7: 85457 | H7: 79 | I7: Active | J7: Finance | K7: 85457 | L7: 3.23 | M7: Achiving
A8: EMP032 | B8: Jessica | C8: Johnson | D8: Jessica Johnson | E8: FIN03 | F8: 42565 | G8: 100851 | H8: 64 | I8: Active | J8: Finance | K8: 100851 | L8: 10 | M8: Developing
A9: EMP099 | B9: Michael | C9: Wilson | D9: Michael Wilson | E9: FIN03 | F9: 43233 | G9: 85312 | H9: 66 | I9: Active | J9: Finance | K9: 85312 | L9: 8.17 | M9: Developing
A10: EMP085 | B10: Emily | C10: Jones | D10: Emily Jones | E10: FIN03 | F10: 42919 | G10: 113389 | H10: 30 | I10: Active | J10: Finance | K10: 113389 | L10: 9.03 | M10: Needs Improvement
A11: EMP053 | B11: Richard | C11: Williams | D11: Richard Williams | E11: FIN03 | F11: 10/22/2015 | G11: 87938.5 | H11: 62 | I11: Active | J11: Finance | K11: 87938.5 | L11: 10.73 | M11: Developing
A12: EMP028 | B12: Thomas | C12: Rodriguez | D12: Thomas Rodriguez | E12: FIN03 | F12: 10/07/2019 | G12: 55920 | H12: 84 | I12: Active | J12: Finance | K12: 55920 | L12: 6.77 | M12: Achiving
A13: EMP058 | B13: Melissa | C13: Johnson | D13: Melissa Johnson | E13: FIN03 | F13: 43091 | G13: 88005 | H13: 69 | I13: Active | J13: Finance | K13: 88005 | L13: 8.56 | M13: Developing
A14: EMP011 | B14: Jane | C14: Davis | D14: Jane Davis | E14: FIN03 | F14: 42838 | G14: 103891 | H14: 80 | I14: Active | J14: Finance | K14: 103891 | L14: 9.26 | M14: Achiving
A15: EMP051 | B15: Jane | C15: Davis | D15: Jane Davis | E15: FIN03 | F15: 42433 | G15: 46390 | H15: 95 | I15: Active | J15: Finance | K15: 46390 | L15: 10.36 | M15: Outstanding
A16: EMP062 | B16: Thomas | C16: Williams | D16: Thomas Williams | E16: FIN03 | F16: 44759 | G16: 98299 | H16: 61 | I16: Active | J16: Finance | K16: 98299 | L16: 3.99 | M16: Developing
A17: EMP074 | B17: David | C17: Williams | D17: David Williams | E17: FIN03 | F17: 44234 | G17: 87938.5 | H17: 68 | I17: Active | J17: Finance | K17: 87938.5 | L17: 5.44 | M17: Developing
A18: EMP125 | B18: Jane | C18: Martinez | D18: Jane Martinez | E18: HR01 | F18: 44578 | G18: 59899 | H18: 78 | I18: Active | J18: Human Resources | K18: 59899 | L18: 4.49 | M18: Achiving
A19: EMP069 | B19: Jane | C19: Davis | D19: Jane Davis | E19: HR01 | F19: 44612 | G19: 93290 | H19: 53 | I19: Active | J19: Human Resources | K19: 93290 | L19: 4.4 | M19: Developing
A20: EMP119 | B20: Emily | C20: Garcia | D20: Emily Garcia | E20: HR01 | F20: 44189 | G20: 118947 | H20: 96 | I20: Active | J20: Human Resources | K20: 118947 | L20: 5.56 | M20: Outstanding
A21: EMP033 | B21: David | C21: Martinez | D21: David Martinez | E21: HR01 | F21: 02/07/2018 | G21: 91655 | H21: 95 | I21: Active | J21: Human Resources | K21: 91655 | L21: 8.44 | M21: Outstanding
A22: EMP067 | B22: Michael | C22: Anderson | D22: Michael Anderson | E22: HR01 | F22: 44079 | G22: 114748 | H22: 33 | I22: Active | J22: Human Resources | K22: 114748 | L22: 5.86 | M22: Needs Improvement
A23: EMP049 | B23: David | C23: Anderson | D23: David Anderson | E23: HR01 | F23: 42944 | G23: $115,618 | H23: 42 | I23: Active | J23: Human Resources | K23: $115,618 | L23: 8.96 | M23: Needs Improvement
A24: EMP065 | B24: Melissa | C24: Williams | D24: Melissa Williams | E24: HR01 | F24: 44402 | G24: 88223.692 | H24: 36 | I24: Active | J24: Human Resources | K24: 88223.692 | L24: 4.97 | M24: Needs Improvement
A25: EMP045 | B25: Robert | C25: Miller | D25: Robert Miller | E25: HR01 | F25: 43008 | G25: 55270 | H25: 87 | I25: Active | J25: Human Resources | K25: 55270 | L25: 8.79 | M25: Exceeding
A26: EMP108 | B26: David | C26: Williams | D26: David Williams | E26: HR01 | F26: 43301 | G26: 85151 | H26: 35 | I26: Active | J26: Human Resources | K26: 85151 | L26: 7.99 | M26: Needs Improvement
A27: EMP048 | B27: Richard | C27: Smith | D27: Richard Smith | E27: HR01 | F27: 09/29/2018 | G27: $47,694 | H27: 75 | I27: Active | J27: Human Resources | K27: $47,694 | L27: 7.79 | M27: Achiving
A28: EMP121 | B28: James | C28: Johnson | D28: James Johnson | E28: HR01 | F28: 44053 | G28: $68,092 | H28: 93 | I28: Active | J28: Human Resources | K28: $68,092 | L28: 5.93 | M28: Exceeding
A29: EMP063 | B29: Emily | C29: Gonzalez | D29: Emily Gonzalez | E29: HR01 | F29: 43796 | G29: 86232 | H29: 93 | I29: Active | J29: Human Resources | K29: 86232 | L29: 6.63 | M29: Exceeding
A30: EMP006 | B30: Jessica | C30: Anderson | D30: Jessica Anderson | E30: HR01 | F30: 42304 | G30: 56073 | H30: 79 | I30: Active | J30: Human Resources | K30: 56073 | L30: 10.72 | M30: Achiving
A31: EMP138 | B31: Sarah | C31: Rodriguez | D31: Sarah Rodriguez | E31: HR01 | F31: 04/20/2023 | G31: 115260 | H31: 77 | I31: Active | J31: Human Resources | K31: 115260 | L31: 3.24 | M31: Achiving
A32: EMP143 | B32: Jessica | C32: Gonzalez | D32: Jessica Gonzalez | E32: HR01 | F32: 42687 | G32: $77,737 | H32: 77 | I32: Active | J32: Human Resources | K32: $77,737 | L32: 9.67 | M32: Achiving
A33: EMP127 | B33: Emily | C33: Brown | D33: Emily Brown | E33: IT02 | F33: 43093 | G33: 50361 | H33: 52 | I33: Active | J33: Information Technology | K33: 50361 | L33: 8.56 | M33: Developing | N33: #N/A
A34: EMP103 | B34: Amanda | C34: Brown | D34: Amanda Brown | E34: IT02 | F34: 44848 | G34: $118,634 | H34: 91 | I34: Active | J34: Information Technology | K34: $118,634 | L34: 3.75 | M34: Exceeding
A35: EMP057 | B35: Emily | C35: Hernandez | D35: Emily Hernandez | E35: IT02 | F35: 42425 | G35: 76918 | H35: 62 | I35: Active | J35: Information Technology | K35: 76918 | L35: 10.39 | M35: Developing
A36: EMP126 | B36: Emily | C36: Davis | D36: Emily Davis | E36: IT02 | F36: 42337 | G36: 105765 | H36: 42 | I36: Active | J36: Information Technology | K36: 105765 | L36: 10.63 | M36: Needs Improvement
A37: EMP120 | B37: Amanda | C37: Gonzalez | D37: Amanda Gonzalez | E37: IT02 | F37: 42575 | G37: 79893.409 | H37: 75 | I37: Active | J37: Information Technology | K37: 79893.409 | L37: 9.98 | M37: Achiving
A38: EMP146 | B38: Thomas | C38: Rodriguez | D38: Thomas Rodriguez | E38: IT02 | F38: 44765 | G38: $50,873 | H38: 90 | I38: Active | J38: Information Technology | K38: $50,873 | L38: 3.98 | M38: Exceeding
A39: EMP137 | B39: Michael | C39: Johnson | D39: Michael Johnson | E39: IT02 | F39: 45195 | G39: 66069 | H39: 72 | I39: Active | J39: Information Technology | K39: 66069 | L39: 2.8 | M39: Achiving
A40: EMP056 | B40: Sarah | C40: Brown | D40: Sarah Brown | E40: IT02 | F40: 43626 | G40: 90157 | H40: 58 | I40: Active | J40: Information Technology | K40: 90157 | L40: 7.1 | M40: Developing
A41: EMP106 | C41: Brown | D41: Brown | E41: IT02 | F41: 42248 | G41: 102691 | H41: 52 | I41: Active | J41: Information Technology | K41: 102691 | L41: 10.87 | M41: Developing
...
